[2025-05-20T23:36:03.683+0000] {local_task_job_runner.py:123} INFO - ::group::Pre task execution logs
[2025-05-20T23:36:03.728+0000] {taskinstance.py:2614} INFO - Dependencies all met for dep_context=non-requeueable deps ti=<TaskInstance: merge_sources_pipeline.preprocessing manual__2025-05-20T23:21:58.810763+00:00 [queued]>
[2025-05-20T23:36:03.747+0000] {taskinstance.py:2614} INFO - Dependencies all met for dep_context=requeueable deps ti=<TaskInstance: merge_sources_pipeline.preprocessing manual__2025-05-20T23:21:58.810763+00:00 [queued]>
[2025-05-20T23:36:03.748+0000] {taskinstance.py:2867} INFO - Starting attempt 1 of 2
[2025-05-20T23:36:03.778+0000] {taskinstance.py:2890} INFO - Executing <Task(_PythonDecoratedOperator): preprocessing> on 2025-05-20 23:21:58.810763+00:00
[2025-05-20T23:36:03.799+0000] {standard_task_runner.py:72} INFO - Started process 824 to run task
[2025-05-20T23:36:03.809+0000] {standard_task_runner.py:104} INFO - Running: ['***', 'tasks', 'run', 'merge_sources_pipeline', 'preprocessing', 'manual__2025-05-20T23:21:58.810763+00:00', '--job-id', '27', '--raw', '--subdir', 'DAGS_FOLDER/inference_dag.py', '--cfg-path', '/tmp/tmpe0n1igdl']
[2025-05-20T23:36:03.816+0000] {standard_task_runner.py:105} INFO - Job 27: Subtask preprocessing
[2025-05-20T23:36:03.921+0000] {task_command.py:467} INFO - Running <TaskInstance: merge_sources_pipeline.preprocessing manual__2025-05-20T23:21:58.810763+00:00 [running]> on host 0a7de9743f25
[2025-05-20T23:36:04.108+0000] {taskinstance.py:3134} INFO - Exporting env vars: AIRFLOW_CTX_DAG_OWNER='***' AIRFLOW_CTX_DAG_ID='merge_sources_pipeline' AIRFLOW_CTX_TASK_ID='preprocessing' AIRFLOW_CTX_EXECUTION_DATE='2025-05-20T23:21:58.810763+00:00' AIRFLOW_CTX_TRY_NUMBER='1' AIRFLOW_CTX_DAG_RUN_ID='manual__2025-05-20T23:21:58.810763+00:00'
[2025-05-20T23:36:04.111+0000] {taskinstance.py:732} INFO - ::endgroup::
[2025-05-20T23:36:04.123+0000] {taskinstance.py:3315} ERROR - Task failed due to SystemExit(Validation Error: Missing required columns in input data: ['distance_flown_km'])
[2025-05-20T23:36:04.147+0000] {taskinstance.py:1226} INFO - Marking task as UP_FOR_RETRY. dag_id=merge_sources_pipeline, task_id=preprocessing, run_id=manual__2025-05-20T23:21:58.810763+00:00, execution_date=20250520T232158, start_date=20250520T233603, end_date=20250520T233604
[2025-05-20T23:36:04.210+0000] {taskinstance.py:341} INFO - ::group::Post task execution logs
[2025-05-20T23:36:04.211+0000] {standard_task_runner.py:124} ERROR - Failed to execute job 27 for task preprocessing (Task failed due to SystemExit(Validation Error: Missing required columns in input data: ['distance_flown_km']); 824)
Traceback (most recent call last):
  File "/opt/airflow/scripts/preprocess.py", line 27, in preprocess_df
    validate_input(df)
  File "/opt/airflow/scripts/preprocess.py", line 10, in validate_input
    raise ValueError(f"Missing required columns in input data: {missing_cols}")
ValueError: Missing required columns in input data: ['distance_flown_km']

During handling of the above exception, another exception occurred:

Traceback (most recent call last):
  File "/home/airflow/.local/lib/python3.10/site-packages/airflow/models/taskinstance.py", line 274, in _run_raw_task
    TaskInstance._execute_task_with_callbacks(
  File "/home/airflow/.local/lib/python3.10/site-packages/airflow/models/taskinstance.py", line 3161, in _execute_task_with_callbacks
    result = self._execute_task(context, task_orig)
  File "/home/airflow/.local/lib/python3.10/site-packages/airflow/models/taskinstance.py", line 3185, in _execute_task
    return _execute_task(self, context, task_orig)
  File "/home/airflow/.local/lib/python3.10/site-packages/airflow/models/taskinstance.py", line 768, in _execute_task
    result = _execute_callable(context=context, **execute_callable_kwargs)
  File "/home/airflow/.local/lib/python3.10/site-packages/airflow/models/taskinstance.py", line 734, in _execute_callable
    return ExecutionCallableRunner(
  File "/home/airflow/.local/lib/python3.10/site-packages/airflow/utils/operator_helpers.py", line 252, in run
    return self.func(*args, **kwargs)
  File "/home/airflow/.local/lib/python3.10/site-packages/airflow/models/baseoperator.py", line 424, in wrapper
    return func(self, *args, **kwargs)
  File "/home/airflow/.local/lib/python3.10/site-packages/airflow/decorators/base.py", line 266, in execute
    return_value = super().execute(context)
  File "/home/airflow/.local/lib/python3.10/site-packages/airflow/models/baseoperator.py", line 424, in wrapper
    return func(self, *args, **kwargs)
  File "/home/airflow/.local/lib/python3.10/site-packages/airflow/operators/python.py", line 238, in execute
    return_value = self.execute_callable()
  File "/home/airflow/.local/lib/python3.10/site-packages/airflow/operators/python.py", line 256, in execute_callable
    return runner.run(*self.op_args, **self.op_kwargs)
  File "/home/airflow/.local/lib/python3.10/site-packages/airflow/utils/operator_helpers.py", line 252, in run
    return self.func(*args, **kwargs)
  File "/opt/airflow/dags/inference_dag.py", line 61, in preprocessing
    preprocessed_df = preprocess_df(merged_df, training=False)
  File "/opt/airflow/scripts/preprocess.py", line 29, in preprocess_df
    sys.exit(f"Validation Error: {e}")
  File "/home/airflow/.local/lib/python3.10/site-packages/billiard/pool.py", line 283, in exit
    return _exit(status)
SystemExit: Validation Error: Missing required columns in input data: ['distance_flown_km']

During handling of the above exception, another exception occurred:

Traceback (most recent call last):
  File "/home/airflow/.local/lib/python3.10/site-packages/airflow/task/task_runner/standard_task_runner.py", line 117, in _start_by_fork
    ret = args.func(args, dag=self.dag)
  File "/home/airflow/.local/lib/python3.10/site-packages/airflow/cli/cli_config.py", line 49, in command
    return func(*args, **kwargs)
  File "/home/airflow/.local/lib/python3.10/site-packages/airflow/utils/cli.py", line 116, in wrapper
    return f(*args, **kwargs)
  File "/home/airflow/.local/lib/python3.10/site-packages/airflow/cli/commands/task_command.py", line 483, in task_run
    task_return_code = _run_task_by_selected_method(args, _dag, ti)
  File "/home/airflow/.local/lib/python3.10/site-packages/airflow/cli/commands/task_command.py", line 256, in _run_task_by_selected_method
    return _run_raw_task(args, ti)
  File "/home/airflow/.local/lib/python3.10/site-packages/airflow/cli/commands/task_command.py", line 341, in _run_raw_task
    return ti._run_raw_task(
  File "/home/airflow/.local/lib/python3.10/site-packages/airflow/utils/session.py", line 97, in wrapper
    return func(*args, session=session, **kwargs)
  File "/home/airflow/.local/lib/python3.10/site-packages/airflow/models/taskinstance.py", line 3006, in _run_raw_task
    return _run_raw_task(
  File "/home/airflow/.local/lib/python3.10/site-packages/airflow/models/taskinstance.py", line 335, in _run_raw_task
    raise AirflowException(msg)
airflow.exceptions.AirflowException: Task failed due to SystemExit(Validation Error: Missing required columns in input data: ['distance_flown_km'])
[2025-05-20T23:36:04.266+0000] {local_task_job_runner.py:266} INFO - Task exited with return code 1
[2025-05-20T23:36:04.319+0000] {taskinstance.py:3901} INFO - 0 downstream tasks scheduled from follow-on schedule check
[2025-05-20T23:36:04.323+0000] {local_task_job_runner.py:245} INFO - ::endgroup::
